Workbook

Sheet README
A1: CSA AISMM ↔ NIST AI RMF ↔ ISO/IEC 42001 Mapping Workbook
A2: Purpose | B2: A working crosswalk that maps CSA AI Security Maturity Model control objectives to NIST AI RMF functions/categories and ISO/IEC 42001 AIMS clauses / Annex A control objectives.
A3: How to use | B3: Filter the Mapping sheet by CSA domain, maturity level, deployment type, NIST function, or ISO clause/Annex area. Use the notes column to convert mappings into audit evidence and implementation backlog items.
A4: Mapping method | B4: Direct references from the AISMM External References column were prioritized. Where AISMM did not cite NIST/ISO explicitly, mappings were derived from the CSA domain/theme and control objective text.
A5: Key caveat | B5: This is an implementation crosswalk, not a formal certification equivalence statement. ISO/IEC 42001 certification requires conforming to the standard and audit evidence in your organizational context.
A6: Primary sources | B6: CSA AISMM page: https://cloudsecurityalliance.org/artifacts/ai-security-maturity-model
B7: NIST AI RMF page: https://www.nist.gov/itl/ai-risk-management-framework
B8: NIST AI RMF Core: https://airc.nist.gov/airmf-resources/airmf/5-sec-core/
B9: ISO/IEC 42001 page: https://www.iso.org/standard/42001
B10: Uploaded sources: AISMM_v3.7_20260507.xlsx, nist_ai_rmf_playbook.xlsx, ISO 42001 checklist PDF
A12: Update | B12: Added requested control-language columns.
A13: NIST Control Language | B13: Pulled from the uploaded NIST AI RMF Playbook spreadsheet: subcategory action guidance is displayed next to each NIST ID.
A14: ISO Control Language | B14: Pulled from the uploaded ISO 42001 checklist: clause and Annex A checklist criteria/summaries are displayed next to each ISO mapping.
A15: Caution | B15: The ISO language is checklist-based mapping support, not verbatim ISO standard text or certification advice.
A17: Assessment model added | B17: Columns S:AN on the Mapping sheet turn the crosswalk into an assessment worksheet.
A18: Maturity scoring | B18: Use 0-5 scale from the Maturity_Rubric sheet. Target score can be adjusted by risk tier or organization policy.
A19: Framework compliance | B19: CSA result compares current maturity to AISMM target level. NIST and ISO compliance require mapped control, score >=3, and Validated evidence.
A20: Evidence guidance | B20: Suggested reference evidence and verification tests are populated from Evidence_Library by CSA prefix.
A21: Dashboard | B21: Assessment_Dashboard summarizes maturity, compliance, validated evidence, and open gaps.
A22: Source note | B22: ISO control language in this workbook is checklist-derived support language, not verbatim ISO standard text.
A23: Public references | B23: CSA AISMM artifact: https://cloudsecurityalliance.org/artifacts/ai-security-maturity-model ; NIST AI RMF Core: https://airc.nist.gov/airmf-resources/airmf/5-sec-core/ ; ISO overview: https://www.iso.org/obp/ui/en/

Sheet Mapping
A1: CSA Domain | B1: CSA Control ID | C1: CSA Prefix | D1: Maturity Level | E1: CSA Control Objective | F1: CSA Control Description | G1: Automated or Manual | H1: Deployment Types | I1: CSA AICM Mapping | J1: NIST AI RMF Control ID(s) | K1: NIST AI RMF Control Language / Playbook Actions | L1: NIST Mapping Basis | M1: ISO/IEC 42001 Clause / Annex Control ID(s) | N1: ISO/IEC 42001 Control Language / Checklist Criteria | O1: ISO Mapping Basis | P1: Evidence / Implementation Notes | Q1: Source / Traceability | R1: AISMM External References | S1: Applicable? | T1: Mapped Frameworks In Scope | U1: Business Unit / AI System | V1: Control Owner | W1: Current Implementation Status | X1: Current Maturity Score (0-5) | Y1: Target Maturity Score (0-5) | Z1: Maturity Gap | AA1: CSA AISMM Maturity Result | AB1: NIST AI RMF Compliance Result | AC1: ISO/IEC 42001 Compliance Result | AD1: Frameworks Complied To | AE1: Evidence Status | AF1: Evidence Repository / Link | AG1: Suggested Reference Evidence for Verification | AH1: Verification Test Procedure | AI1: Test Result | AJ1: Assessor Notes | AK1: Remediation Action | AL1: Due Date | AM1: Residual Risk | AN1: Last Assessed
A2: Governance | B2: GOV-02.1 | C2: GOV | D2: 2 | E2: Enterprise AI acceptable use policy with signed personnel attestation | F2: Every employee and contractor with system access has reviewed and assigned the organization's AI policies, which include which AI tools are permitted, what data classifications can go into each, what use cases are prohibited, and how to report incidents or request exceptions. | G2: Manual | H2: All | I2: HRS-15 (AI acceptable use), GRC-09 (acceptable use of AI service), HRS-02 (acceptable use of technology) | J2: GOVERN 1.1; GOVERN 1 | K2: GOVERN 1.1: * Maintain awareness of the applicable legal and regulatory considerations and requirements specific to industry, sector, and business purpose, as well as the application context of the deployed AI system. * Align risk management efforts with applicable legal standards. * Maintain policies for training (and re-training) organizational staff about necessary legal or regulatory considerations that may impact AI-related design, development and deployment activities. | L2: Direct from AISMM external reference | M2: Annex A.2; Annex A.7; Annex A.8; Annex A.9 | N2: Annex A.2 – Policies related to AI: Document and approve AI policy, include responsible AI principles and continual improvement, review policy regularly, and align it to other relevant organizational policies. Annex A.7 – Data for AI systems: Maintain documented AI data management, identify sources and provenance, record intended use, define data quality requirements, and document/justify preparation methods. Annex A.8 – Information for interested parties: Provide necessary documentation to users and interested parties; define incident reporting/escalation, incident communication, and stakeholder information requirements. Annex A.9 – Use of AI systems: Define responsible AI use processes, ethical/appropriate-use objectives, intended-purpose usage boundaries, and monitoring/remediation for misuse or unintended consequences. | O2: Direct from AISMM external reference | P2: Publish approved AI policy/standard; maintain attestation and exception workflow. | Q2: CSA AISMM uploaded spreadsheet; NIST AI RMF Playbook uploaded spreadsheet; ISO 42001 checklist uploaded PDF; public CSA/NIST/ISO pages | R2: NIST AI RMF Govern 1.1; ISO/IEC 42001 AI management system policy requirements | S2: Yes | T2: CSA AISMM; NIST AI RMF; ISO/IEC 42001 | W2: Not Assessed | X2: 0 | Y2: 3 | Z2: =IF($S2="No","N/A",MAX(0,$Y2-$X2)) -> 3 | AA2: =IF($S2="No","N/A",IF($X2>=VALUE($D2),"Meets CSA maturity","Gap to CSA level")) -> Gap to CSA level | AB2: =IF($S2="No","N/A",IF($J2="","Not Mapped",IF(AND($X2>=3,$AE2="Validated"),"Compliant",IF($X2>=1,"Partial","Not Compliant")))) -> Not Compliant | AC2: =IF($S2="No","N/A",IF($M2="","Not Mapped",IF(AND($X2>=3,$AE2="Validated"),"Compliant",IF($X2>=1,"Partial","Not Compliant")))) -> Not Compliant | AD2: =IF($S2="No","N/A",IF(AND($AA2="Meets CSA maturity",$AB2="Compliant",$AC2="Compliant"),"CSA + NIST + ISO",IF(AND($AA2="Meets CSA maturity",$AB2="Compliant"),"CSA + NIST",IF(AND($AA2="Meets CSA maturity",$AC2="Compliant"),"CSA + ISO",IF(AND($AB2="Compliant",$AC2="Compliant"),"NIST + ISO",IF($AA2="Meets CSA maturity","CSA only",IF($AB2="Compliant","NIST only",IF($AC2="Compliant","ISO only","No mapped framework fully compliant")))))))) -> No mapped framework fully compliant | AE2: Not Provided | AG2: =IFERROR(VLOOKUP($C2,Evidence_Library!$A$2:$C$13,2,FALSE),"Control-specific policy/procedure, implementation record, sample evidence, and monitoring proof.") -> AI policy and acceptable-use standard; AI governance charter; AI Council minutes; approval records; exception logs; role/RACI matrix; training/attestation records; AI risk appetite and escalation procedure. | AH2: =IFERROR(VLOOKUP($C2,Evidence_Library!$A$2:$C$13,3,FALSE),"Inspect design, sample implementation evidence, interview owner, and verify operating effectiveness.") -> Inspect approved policy and governance charter; sample approval records; verify owners and decision logs; interview AI Council or control owner; confirm exceptions and attestations are tracked. | AI2: Not Tested | AM2: Not Assessed
A3: Governance | B3: GOV-02.2 | C3: GOV | D3: 2 | E3: Named approval authority for enterprise AI procurement and major deployments | F3: A named approval authority makes and records yes/no decisions before new AI providers are contracted or AI-powered applications ship to production. Teams are not allowed to adopt new AI products or use cases without approval. | G3: Manual | H3: All | I3: GRC-06 (governance responsibility model), GRC-09 (acceptable use of AI service) | J3: GOVERN 2.1; GOVERN 2 | K3: GOVERN 2.1: - Establish policies that define the AI risk management roles and responsibilities for positions directly and indirectly related to AI systems, including, but not limited to - Boards of directors or advisory committees - Senior management - AI audit functions - Product management - Project management - AI design - AI development - Human-AI interaction - AI testing and evaluation - AI acquisition and procurement - Impact assessment functions - Oversight functions - Establish policies that promote regular communication among AI actors participating in AI risk management efforts. - Establish policies that separate management of AI system development functions from AI system testing functions, to enable independent course-correction of AI systems. - Establish policies to identify, increase the transparency of, and prevent conflicts of interest in AI risk management efforts.… | L3: Direct from AISMM external reference | M3: Annex A.3; Annex A.6; Annex A.9; Annex A.10 | N3: Annex A.3 – Internal organization: Define AI roles and responsibilities; provide reporting and confidential escalation paths; investigate and resolve AI-related concerns. Annex A.6 – AI system life cycle: Define responsible development objectives, specify verification and validation, maintain technical documentation, and record/maintain event logs during system use. Annex A.9 – Use of AI systems: Define responsible AI use processes, ethical/appropriate-use objectives, intended-purpose usage boundaries, and monitoring/remediation for misuse or unintended consequences. Annex A.10 – Third-party and customer relationships: Define lifecycle responsibilities with third parties, manage AI suppliers, capture customer expectations, and review third-party roles through ongoing governance. | O3: Derived by control theme/domain | P3: Use this row as a control objective to assess current state, define target maturity, collect evidence, and remediate gaps. | Q3: CSA AISMM uploaded spreadsheet; NIST AI RMF Playbook uploaded spreadsheet; ISO 42001 checklist uploaded PDF; public CSA/NIST/ISO pages | R3: NIST AI RMF Govern 2.1 (roles, responsibilities, accountability) | S3: Yes | T3: CSA AISMM; NIST AI RMF; ISO/IEC 42001 | W3: Not Assessed | X3: 0 | Y3: 3 | Z3: =IF($S3="No","N/A",MAX(0,$Y3-$X3)) -> 3 | AA3: =IF($S3="No","N/A",IF($X3>=VALUE($D3),"Meets CSA maturity","Gap to CSA level")) -> Gap to CSA level | AB3: =IF($S3="No","N/A",IF($J3="","Not Mapped",IF(AND($X3>=3,$AE3="Validated"),"Compliant",IF($X3>=1,"Partial","Not Compliant")))) -> Not Compliant | AC3: =IF($S3="No","N/A",IF($M3="","Not Mapped",IF(AND($X3>=3,$AE3="Validated"),"Compliant",IF($X3>=1,"Partial","Not Compliant")))) -> Not Compliant | AD3: =IF($S3="No","N/A",IF(AND($AA3="Meets CSA maturity",$AB3="Compliant",$AC3="Compliant"),"CSA + NIST + ISO",IF(AND($AA3="Meets CSA maturity",$AB3="Compliant"),"CSA + NIST",IF(AND($AA3="Meets CSA maturity",$AC3="Compliant"),"CSA + ISO",IF(AND($AB3="Compliant",$AC3="Compliant"),"NIST + ISO",IF($AA3="Meets CSA maturity","CSA only",IF($AB3="Compliant","NIST only",IF($AC3="Compliant","ISO only","No mapped framework fully compliant")))))))) -> No mapped framework fully compliant | AE3: Not Provided | AG3: =IFERROR(VLOOKUP($C3,Evidence_Library!$A$2:$C$13,2,FALSE),"Control-specific policy/procedure, implementation record, sample evidence, and monitoring proof.") -> AI policy and acceptable-use standard; AI governance charter; AI Council minutes; approval records; exception logs; role/RACI matrix; training/attestation records; AI risk appetite and escalation procedure. | AH3: =IFERROR(VLOOKUP($C3,Evidence_Library!$A$2:$C$13,3,FALSE),"Inspect design, sample implementation evidence, interview owner, and verify operating effectiveness.") -> Inspect approved policy and governance charter; sample approval records; verify owners and decision logs; interview AI Council or control owner; confirm exceptions and attestations are tracked. | AI3: Not Tested | AM3: Not Assessed
A4: Governance | B4: GOV-03.1 | C4: GOV | D4: 3 | E4: AI Council issues and maintains a catalog of approved use cases with provider and data type mappings | F4: A cross-functional AI Council (or equivalent body) publishes a catalog of approved AI use cases, mapped to approved AI providers/technologies and data types. Use cases include examples like AI coding tools, customer service agents, AI data analytics platforms. These map to specific providers and which data types are allowed per use case and provider (e.g. PII). | G4: Manual | H4: All | I4: GRC-01 (governance program policy), GRC-06 (governance responsibility model), GRC-09 (acceptable use of AI service) | J4: GOVERN 1.2; GOVERN 2.1; GOVERN 1; GOVERN 2 | K4: GOVERN 1.2: Organizational AI risk management policies should be designed to: - Define key terms and concepts related to AI systems and the scope of their purposes and intended uses. - Connect AI governance to existing organizational governance and risk controls. - Align to broader data governance policies and practices, particularly the use of sensitive or otherwise risky data. - Detail standards for experimental design, data quality, and model training. - Outline and document risk mapping and measurement processes and standards. - Detail model testing and validation processes. - Detail review processes for legal and risk functions. - Establish the frequency of and detail for monitoring, auditing and review processes. - Outline change management requirements. - Outline processes for internal and external stakeholder engagement.… GOVERN 2.1: - Establish policies that define the AI risk management roles and responsibilities for positions directly and indirectly related to AI systems, including, but not limited to - Boards of directors or advisory committees - Senior management - AI audit functions - Product management - Project management - AI design - AI development - Human-AI interaction - AI testing and evaluation - AI acquisition and procurement - Impact assessment functions - Oversight functions - Establish policies that promote regular communication among AI actors participating in AI risk management efforts. - Establish policies that separate management of AI system development functions from AI system testing functions, to enable independent course-correction of AI systems. - Establish policies to identify, increase the transparency of, and prevent conflicts of interest in AI risk management efforts.… | L4: Direct from AISMM external reference | M4: Clause 5; Annex A.6 | N4: Clause 5 – Leadership: Top management demonstrates commitment to the AIMS, establishes an AI policy aligned to strategy, and assigns/communicates AI management roles, responsibilities, and authorities. Annex A.6 – AI system life cycle: Define responsible development objectives, specify verification and validation, maintain technical documentation, and record/maintain event logs during system use. | O4: Direct from AISMM external reference | P4: Tie provider/model/library onboarding to supplier risk, licensing, model/data provenance, and AI-BOM/SBOM records. | Q4: CSA AISMM uploaded spreadsheet; NIST AI RMF Playbook uploaded spreadsheet; ISO 42001 checklist uploaded PDF; public CSA/NIST/ISO pages | R4: NIST AI RMF Govern 1.2, Govern 2.1; ISO/IEC 42001 Clause 5 (leadership) and Annex A.6 (AI system life cycle) | S4: Yes | T4: CSA AISMM; NIST AI RMF; ISO/IEC 42001 | W4: Not Assessed | X4: 0 | Y4: 3 | Z4: =IF($S4="No","N/A",MAX(0,$Y4-$X4)) -> 3 | AA4: =IF($S4="No","N/A",IF($X4>=VALUE($D4),"Meets CSA maturity","Gap to CSA level")) -> Gap to CSA level | AB4: =IF($S4="No","N/A",IF($J4="","Not Mapped",IF(AND($X4>=3,$AE4="Validated"),"Compliant",IF($X4>=1,"Partial","Not Compliant")))) -> Not Compliant | AC4: =IF($S4="No","N/A",IF($M4="","Not Mapped",IF(AND($X4>=3,$AE4="Validated"),"Compliant",IF($X4>=1,"Partial","Not Compliant")))) -> Not Compliant | AD4: =IF($S4="No","N/A",IF(AND($AA4="Meets CSA maturity",$AB4="Compliant",$AC4="Compliant"),"CSA + NIST + ISO",IF(AND($AA4="Meets CSA maturity",$AB4="Compliant"),"CSA + NIST",IF(AND($AA4="Meets CSA maturity",$AC4="Compliant"),"CSA + ISO",IF(AND($AB4="Compliant",$AC4="Compliant"),"NIST + ISO",IF($AA4="Meets CSA maturity","CSA only",IF($AB4="Compliant","NIST only",IF($AC4="Compliant","ISO only","No mapped framework fully compliant")))))))) -> No mapped framework fully compliant | AE4: Not Provided | AG4: =IFERROR(VLOOKUP($C4,Evidence_Library!$A$2:$C$13,2,FALSE),"Control-specific policy/procedure, implementation record, sample evidence, and monitoring proof.") -> AI policy and acceptable-use standard; AI governance charter; AI Council minutes; approval records; exception logs; role/RACI matrix; training/attestation records; AI risk appetite and escalation procedure. | AH4: =IFERROR(VLOOKUP($C4,Evidence_Library!$A$2:$C$13,3,FALSE),"Inspect design, sample implementation evidence, interview owner, and verify operating effectiveness.") -> Inspect approved policy and governance charter; sample approval records; verify owners and decision logs; interview AI Council or control owner; confirm exceptions and attestations are tracked. | AI4: Not Tested | AM4: Not Assessed
A5: Governance | B5: GOV-03.2 | C5: GOV | D5: 3 | E5: Authoritative AI deployment and application registry | F5: The AI Council maintains an authoritative registry of AI deployments and applications, with each entry linked to the approved use case it serves under GOV-03.1, the owning team, and the underlying models, agents, and MCP integrations in use. The registry is the canonical record of what AI runs under what approval. | G5: Either | H5: All | I5: GRC-05 (information security program scope), GRC-01 (governance program policy) | J5: MAP 1.1; MAP 1 | K5: MAP 1.1: - Maintain awareness of industry, technical, and applicable legal standards. - Examine trustworthiness of AI system design and consider, non-AI solutions - Consider intended AI system design tasks along with unanticipated purposes in collaboration with human factors and socio-technical domain experts. - Define and document the task, purpose, minimum functionality, and benefits of the AI system to inform considerations about whether the utility of the project or its lack of. - Identify whether there are non-AI or non-technology alternatives that will lead to more trustworthy outcomes. - Examine how changes in system performance affect downstream events such as decision-making (e.g: changes in an AI model objective function create what types of impacts in how many candidates do/do not get a job interview).… | L5: Direct from AISMM external reference | M5: Annex A.6 | N5: Annex A.6 – AI system life cycle: Define responsible development objectives, specify verification and validation, maintain technical documentation, and record/maintain event logs during system use. | O5: Direct from AISMM external reference | P5: Maintain authoritative AI inventory; link assets to owners, use cases, providers, data classes, and risk tiers. | Q5: CSA AISMM uploaded spreadsheet; NIST AI RMF Playbook uploaded spreadsheet; ISO 42001 checklist uploaded PDF; public CSA/NIST/ISO pages | R5: NIST AI RMF Map 1.1 (AI system context); ISO/IEC 42001 Annex A.6.2 (AI system inventory) | S5: Yes | T5: CSA AISMM; NIST AI RMF; ISO/IEC 42001 | W5: Not Assessed | X5: 0 | Y5: 3 | Z5: =IF($S5="No","N/A",MAX(0,$Y5-$X5)) -> 3 | AA5: =IF($S5="No","N/A",IF($X5>=VALUE($D5),"Meets CSA maturity","Gap to CSA level")) -> Gap to CSA level | AB5: =IF($S5="No","N/A",IF($J5="","Not Mapped",IF(AND($X5>=3,$AE5="Validated"),"Compliant",IF($X5>=1,"Partial","Not Compliant")))) -> Not Compliant | AC5: =IF($S5="No","N/A",IF($M5="","Not Mapped",IF(AND($X5>=3,$AE5="Validated"),"Compliant",IF($X5>=1,"Partial","Not Compliant")))) -> Not Compliant | AD5: =IF($S5="No","N/A",IF(AND($AA5="Meets CSA maturity",$AB5="Compliant",$AC5="Compliant"),"CSA + NIST + ISO",IF(AND($AA5="Meets CSA maturity",$AB5="Compliant"),"CSA + NIST",IF(AND($AA5="Meets CSA maturity",$AC5="Compliant"),"CSA + ISO",IF(AND($AB5="Compliant",$AC5="Compliant"),"NIST + ISO",IF($AA5="Meets CSA maturity","CSA only",IF($AB5="Compliant","NIST only",IF($AC5="Compliant","ISO only","No mapped framework fully compliant")))))))) -> No mapped framework fully compliant | AE5: Not Provided | AG5: =IFERROR(VLOOKUP($C5,Evidence_Library!$A$2:$C$13,2,FALSE),"Control-specific policy/procedure, implementation record, sample evidence, and monitoring proof.") -> AI policy and acceptable-use standard; AI governance charter; AI Council minutes; approval records; exception logs; role/RACI matrix; training/attestation records; AI risk appetite and escalation procedure. | AH5: =IFERROR(VLOOKUP($C5,Evidence_Library!$A$2:$C$13,3,FALSE),"Inspect design, sample implementation evidence, interview owner, and verify operating effectiveness.") -> Inspect approved policy and governance charter; sample approval records; verify owners and decision logs; interview AI Council or control owner; confirm exceptions and attestations are tracked. | AI5: Not Tested | AM5: Not Assessed
A6: Governance | B6: GOV-03.3 | C6: GOV | D6: 3 | E6: Role-based AI training with measured completion | F6: Employees receive AI training aligned with their job role. E.g. a baseline for everyone, a developer track for those using coding assistants or building AI applications, and a high-risk-role track for functions whose AI use affects customer, employee, or regulated decisions. Completion is tracked. | G6: Automated | H6: All | I6: HRS-14 (AI competency training), HRS-11 (security awareness training), HRS-15 (AI acceptable use) | J6: GOVERN 3.2; GOVERN 6.2; GOVERN 3; GOVERN 6 | K6: GOVERN 3.2: - Establish policies and procedures that define and differentiate the various human roles and responsibilities when using, interacting with, or monitoring AI systems. - Establish procedures for capturing and tracking risk information related to human-AI configurations and associated outcomes. - Establish policies for the development of proficiency standards for AI actors carrying out system operation tasks and system oversight tasks. - Establish specified risk management training protocols for AI actors carrying out system operation tasks and system oversight tasks. - Establish policies and procedures regarding AI actor roles, and responsibilities for human oversight of deployed systems.… GOVERN 6.2: - Establish policies for handling third-party system failures to include consideration of redundancy mechanisms for vital third-party AI systems. - Verify that incident response plans address third-party AI systems. | L6: Direct from AISMM external reference | M6: Clause 7 | N6: Clause 7 – Support: Provide AIMS resources; ensure competence, awareness, communication, and control of documented information. | O6: Direct from AISMM external reference | P6: Track role-based completion, knowledge checks, and refresh cadence. | Q6: CSA AISMM uploaded spreadsheet; NIST AI RMF Playbook uploaded spreadsheet; ISO 42001 checklist uploaded PDF; public CSA/NIST/ISO pages | R6: NIST AI RMF Govern 3.2, Govern 6.2; ISO/IEC 42001 Clause 7.2 (competence) and Clause 7.3 (awareness) | S6: Yes | T6: CSA AISMM; NIST AI RMF; ISO/IEC 42001 | W6: Not Assessed | X6: 0 | Y6: 3 | Z6: =IF($S6="No","N/A",MAX(0,$Y6-$X6)) -> 3 | AA6: =IF($S6="No","N/A",IF($X6>=VALUE($D6),"Meets CSA maturity","Gap to CSA level")) -> Gap to CSA level | AB6: =IF($S6="No","N/A",IF($J6="","Not Mapped",IF(AND($X6>=3,$AE6="Validated"),"Compliant",IF($X6>=1,"Partial","Not Compliant")))) -> Not Compliant | AC6: =IF($S6="No","N/A",IF($M6="","Not Mapped",IF(AND($X6>=3,$AE6="Validated"),"Compliant",IF($X6>=1,"Partial","Not Compliant")))) -> Not Compliant | AD6: =IF($S6="No","N/A",IF(AND($AA6="Meets CSA maturity",$AB6="Compliant",$AC6="Compliant"),"CSA + NIST + ISO",IF(AND($AA6="Meets CSA maturity",$AB6="Compliant"),"CSA + NIST",IF(AND($AA6="Meets CSA maturity",$AC6="Compliant"),"CSA + ISO",IF(AND($AB6="Compliant",$AC6="Compliant"),"NIST + ISO",IF($AA6="Meets CSA maturity","CSA only",IF($AB6="Compliant","NIST only",IF($AC6="Compliant","ISO only","No mapped framework fully compliant")))))))) -> No mapped framework fully compliant | AE6: Not Provided | AG6: =IFERROR(VLOOKUP($C6,Evidence_Library!$A$2:$C$13,2,FALSE),"Control-specific policy/procedure, implementation record, sample evidence, and monitoring proof.") -> AI policy and acceptable-use standard; AI governance charter; AI Council minutes; approval records; exception logs; role/RACI matrix; training/attestation records; AI risk appetite and escalation procedure. | AH6: =IFERROR(VLOOKUP($C6,Evidence_Library!$A$2:$C$13,3,FALSE),"Inspect design, sample implementation evidence, interview owner, and verify operating effectiveness.") -> Inspect approved policy and governance charter; sample approval records; verify owners and decision logs; interview AI Council or control owner; confirm exceptions and attestations are tracked. | AI6: Not Tested | AM6: Not Assessed
A7: Governance | B7: GOV-04.1 | C7: GOV | D7: 4 | E7: AI Council issues written standards that downstream categories enforce | F7: The AI Council adopts an enterprise standard based on an industry framework, such as the AICM, which is communicated and integrated into downstream requirements. | G7: Manual | H7: All | I7: GRC-01 (governance program policy), GRC-06 (governance responsibility model), GRC-09 (acceptable use of AI service) | J7: GOVERN 1.3; GOVERN 2.3; GOVERN 1; GOVERN 2 | K7: GOVERN 1.3: - Establish policies to define mechanisms for measuring or understanding an AI system’s potential impacts, e.g., via regular impact assessments at key stages in the AI lifecycle, connected to system impacts and frequency of system updates. - Establish policies to define mechanisms for measuring or understanding the likelihood of an AI system’s impacts and their magnitude at key stages in the AI lifecycle. - Establish policies that define assessment scales for measuring potential AI system impact. Scales may be qualitative, such as red-amber-green (RAG), or may entail simulations or econometric approaches. - Establish policies for assigning an overall risk measurement approach for an AI system, or its important components, e.g., via multiplication or combination of a mapped risk’s impact and likelihood (risk ≈ impact x likelihood).… GOVERN 2.3: - Organizational management can: - Declare risk tolerances for developing or using AI systems. - Support AI risk management efforts, and play an active role in such efforts. - Integrate a risk and harm prevention mindset throughout the AI lifecycle as part of organizational culture - Support competent risk management executives. - Delegate the power, resources, and authorization to perform risk management to each appropriate level throughout the management chain. - Organizations can establish board committees for AI risk management and oversight functions and integrate those functions within the organization’s broader enterprise risk management approaches. | L7: Direct from AISMM external reference | M7: Annex A.6; Annex A.9 | N7: Annex A.6 – AI system life cycle: Define responsible development objectives, specify verification and validation, maintain technical documentation, and record/maintain event logs during system use. Annex A.9 – Use of AI systems: Define responsible AI use processes, ethical/appropriate-use objectives, intended-purpose usage boundaries, and monitoring/remediation for misuse or unintended consequences. | O7: Direct from AISMM external reference | P7: Publish approved AI policy/standard; maintain attestation and exception workflow. | Q7: CSA AISMM uploaded spreadsheet; NIST AI RMF Playbook uploaded spreadsheet; ISO 42001 checklist uploaded PDF; public CSA/NIST/ISO pages | R7: NIST AI RMF Govern 1.3, Govern 2.3; ISO/IEC 42001 Annex A.6 (AI system life cycle) and Annex A.9 (use of AI systems) | S7: Yes | T7: CSA AISMM; NIST AI RMF; ISO/IEC 42001 | W7: Not Assessed | X7: 0 | Y7: 3 | Z7: =IF($S7="No","N/A",MAX(0,$Y7-$X7)) -> 3 | AA7: =IF($S7="No","N/A",IF($X7>=VALUE($D7),"Meets CSA maturity","Gap to CSA level")) -> Gap to CSA level | AB7: =IF($S7="No","N/A",IF($J7="","Not Mapped",IF(AND($X7>=3,$AE7="Validated"),"Compliant",IF($X7>=1,"Partial","Not Compliant")))) -> Not Compliant | AC7: =IF($S7="No","N/A",IF($M7="","Not Mapped",IF(AND($X7>=3,$AE7="Validated"),"Compliant",IF($X7>=1,"Partial","Not Compliant")))) -> Not Compliant | AD7: =IF($S7="No","N/A",IF(AND($AA7="Meets CSA maturity",$AB7="Compliant",$AC7="Compliant"),"CSA + NIST + ISO",IF(AND($AA7="Meets CSA maturity",$AB7="Compliant"),"CSA + NIST",IF(AND($AA7="Meets CSA maturity",$AC7="Compliant"),"CSA + ISO",IF(AND($AB7="Compliant",$AC7="Compliant"),"NIST + ISO",IF($AA7="Meets CSA maturity","CSA only",IF($AB7="Compliant","NIST only",IF($AC7="Compliant","ISO only","No mapped framework fully compliant")))))))) -> No mapped framework fully compliant | AE7: Not Provided | AG7: =IFERROR(VLOOKUP($C7,Evidence_Library!$A$2:$C$13,2,FALSE),"Control-specific policy/procedure, implementation record, sample evidence, and monitoring proof.") -> AI policy and acceptable-use standard; AI governance charter; AI Council minutes; approval records; exception logs; role/RACI matrix; training/attestation records; AI risk appetite and escalation procedure. | AH7: =IFERROR(VLOOKUP($C7,Evidence_Library!$A$2:$C$13,3,FALSE),"Inspect design, sample implementation evidence, interview owner, and verify operating effectiveness.") -> Inspect approved policy and governance charter; sample approval records; verify owners and decision logs; interview AI Council or control owner; confirm exceptions and attestations are tracked. | AI7: Not Tested | AM7: Not Assessed
A8: Governance | B8: GOV-04.2 | C8: GOV | D8: 4 | E8: Cross-functional ethics and safety review for high-risk AI use cases | F8: No high-risk AI use case reaches production without a cross-functional ethics and safety review that produces a written go / go-with-conditions / no-go disposition. This can be a function of the AI council. | G8: Manual | H8: All | I8: GRC-10 (AI impact assessment), GRC-11 (bias and fairness assessment), GRC-12 (ethics committee), GRC-13 (explainability requirement), GRC-14 (explainability evaluation), GRC-15 (human supervision) | J8: GOVERN 5.1; MEASURE 2.5; MANAGE 1.3; GOVERN 5; MEASURE 2; MANAGE 1 | K8: GOVERN 5.1: - Establish AI risk management policies that explicitly address mechanisms for collecting, evaluating, and incorporating stakeholder and user feedback that could include: - Recourse mechanisms for faulty AI system outputs. - Bug bounties. - Human-centered design. - User-interaction and experience research. - Participatory stakeholder engagement with individuals and communities that may experience negative impacts. - Verify that stakeholder feedback is considered and addressed, including environmental concerns, and across the entire population of intended users, including historically excluded populations, people with disabilities, older people, and those with limited access to the internet and other basic technologies.… MEASURE 2.5: - Define the operating conditions and socio-technical context under which the AI system will be validated. - Define and document processes to establish the system’s operational conditions and limits. - Establish or identify, and document approaches to measure forms of validity, including: - construct validity (the test is measuring the concept it claims to measure) - internal validity (relationship being tested is not influenced by other factors or variables) - external validity (results are generalizable beyond the training condition) - the use of experimental design principles and statistical analyses and modeling. - Assess and document system variance. Standard approaches include confidence intervals, standard deviation, standard error, bootstrapping, or cross-validation. - Establish or identify, and document robustness measures.… MANAGE 1.3: - Observe regulatory and established organizational, sector, discipline, or professional standards and requirements for applying risk tolerances within the organization. - Document procedures for acting on AI system risks related to trustworthiness characteristics. - Prioritize risks involving physical safety, legal liabilities, regulatory compliance, and negative impacts on individuals, groups, or society. - Identify risk response plans and resources and organizational teams for carrying out response functions. - Store risk management and system documentation in an organized, secure repository that is accessible by relevant AI Actors and appropriate personnel. | L8: Direct from AISMM external reference | M8: Annex A.5 | N8: Annex A.5 – Assessing impacts of AI systems: Perform documented, repeatable impact assessments on individuals, groups, or society; update after significant changes; feed findings into design, controls, and stakeholder communication. | O8: Direct from AISMM external reference | P8: Use this row as a control objective to assess current state, define target maturity, collect evidence, and remediate gaps. | Q8: CSA AISMM uploaded spreadsheet; NIST AI RMF Playbook uploaded spreadsheet; ISO 42001 checklist uploaded PDF; public CSA/NIST/ISO pages | R8: NIST AI RMF Govern 5.1, Measure 2.5, Manage 1.3; EU AI Act Article 9 (risk management system) and Article 14 (human oversight) concepts; ISO/IEC 42001 Annex A.5 (responsible use) | S8: Yes | T8: CSA AISMM; NIST AI RMF; ISO/IEC 42001 | W8: Not Assessed | X8: 0 | Y8: 3 | Z8: =IF($S8="No","N/A",MAX(0,$Y8-$X8)) -> 3 | AA8: =IF($S8="No","N/A",IF($X8>=VALUE($D8),"Meets CSA maturity","Gap to CSA level")) -> Gap to CSA level | AB8: =IF($S8="No","N/A",IF($J8="","Not Mapped",IF(AND($X8>=3,$AE8="Validated"),"Compliant",IF($X8>=1,"Partial","Not Compliant")))) -> Not Compliant | AC8: =IF($S8="No","N/A",IF($M8="","Not Mapped",IF(AND($X8>=3,$AE8="Validated"),"Compliant",IF($X8>=1,"Partial","Not Compliant")))) -> Not Compliant | AD8: =IF($S8="No","N/A",IF(AND($AA8="Meets CSA maturity",$AB8="Compliant",$AC8="Compliant"),"CSA + NIST + ISO",IF(AND($AA8="Meets CSA maturity",$AB8="Compliant"),"CSA + NIST",IF(AND($AA8="Meets CSA maturity",$AC8="Compliant"),"CSA + ISO",IF(AND($AB8="Compliant",$AC8="Compliant"),"NIST + ISO",IF($AA8="Meets CSA maturity","CSA only",IF($AB8="Compliant","NIST only",IF($AC8="Compliant","ISO only","No mapped framework fully compliant")))))))) -> No mapped framework fully compliant | AE8: Not Provided | AG8: =IFERROR(VLOOKUP($C8,Evidence_Library!$A$2:$C$13,2,FALSE),"Control-specific policy/procedure, implementation record, sample evidence, and monitoring proof.") -> AI policy and acceptable-use standard; AI governance charter; AI Council minutes; approval records; exception logs; role/RACI matrix; training/attestation records; AI risk appetite and escalation procedure. | AH8: =IFERROR(VLOOKUP($C8,Evidence_Library!$A$2:$C$13,3,FALSE),"Inspect design, sample implementation evidence, interview owner, and verify operating effectiveness.") -> Inspect approved policy and governance charter; sample approval records; verify owners and decision logs; interview AI Council or control owner; confirm exceptions and attestations are tracked. | AI8: Not Tested | AM8: Not Assessed
A9: Governance | B9: GOV-04.3 | C9: GOV | D9: 4 | E9: Executive / board AI risk-committee oversight with defined escalation triggers | F9: Executive and/or board members are actively engaged with the AI council, which includes regular reporting, review, and disposition of anything requiring executive/board feedback. Executive and/or board members sign off on any governance policies from the AI council. | G9: Manual | H9: All | I9: GRC-06 (governance responsibility model), GRC-07 (information security committee), GRC-12 (ethics committee) | J9: GOVERN 2.1; GOVERN 4.1; GOVERN 2; GOVERN 4 | K9: GOVERN 2.1: - Establish policies that define the AI risk management roles and responsibilities for positions directly and indirectly related to AI systems, including, but not limited to - Boards of directors or advisory committees - Senior management - AI audit functions - Product management - Project management - AI design - AI development - Human-AI interaction - AI testing and evaluation - AI acquisition and procurement - Impact assessment functions - Oversight functions - Establish policies that promote regular communication among AI actors participating in AI risk management efforts. - Establish policies that separate management of AI system development functions from AI system testing functions, to enable independent course-correction of AI systems. - Establish policies to identify, increase the transparency of, and prevent conflicts of interest in AI risk management efforts.… GOVERN 4.1: - Establish policies that require inclusion of oversight functions (legal, compliance, risk management) from the outset of the system design process. - Establish policies that promote effective challenge of AI system design, implementation, and deployment decisions, via mechanisms such as the three lines of defense, model audits, or red-teaming – to minimize workplace risks such as groupthink. - Establish policies that incentivize safety-first mindset and general critical thinking and review at an organizational and procedural level. - Establish whistleblower protections for insiders who report on perceived serious problems with AI systems. - Establish policies to integrate a harm and risk prevention mindset throughout the AI lifecycle. | L9: Direct from AISMM external reference | M9: Clause 5; Clause 9 | N9: Clause 5 – Leadership: Top management demonstrates commitment to the AIMS, establishes an AI policy aligned to strategy, and assigns/communicates AI management roles, responsibilities, and authorities. Clause 9 – Performance Evaluation: Monitor, measure, analyze, and evaluate the AIMS; perform internal audits; conduct management review at planned intervals. | O9: Direct from AISMM external reference | P9: Use this row as a control objective to assess current state, define target maturity, collect evidence, and remediate gaps. | Q9: CSA AISMM uploaded spreadsheet; NIST AI RMF Playbook uploaded spreadsheet; ISO 42001 checklist uploaded PDF; public CSA/NIST/ISO pages | R9: NIST AI RMF Govern 2.1, Govern 4.1; ISO/IEC 42001 Clause 5.1 (leadership and commitment), Clause 9.3 (management review) | S9: Yes | T9: CSA AISMM; NIST AI RMF; ISO/IEC 42001 | W9: Not Assessed | X9: 0 | Y9: 3 | Z9: =IF($S9="No","N/A",MAX(0,$Y9-$X9)) -> 3 | AA9: =IF($S9="No","N/A",IF($X9>=VALUE($D9),"Meets CSA maturity","Gap to CSA level")) -> Gap to CSA level | AB9: =IF($S9="No","N/A",IF($J9="","Not Mapped",IF(AND($X9>=3,$AE9="Validated"),"Compliant",IF($X9>=1,"Partial","Not Compliant")))) -> Not Compliant | AC9: =IF($S9="No","N/A",IF($M9="","Not Mapped",IF(AND($X9>=3,$AE9="Validated"),"Compliant",IF($X9>=1,"Partial","Not Compliant")))) -> Not Compliant | AD9: =IF($S9="No","N/A",IF(AND($AA9="Meets CSA maturity",$AB9="Compliant",$AC9="Compliant"),"CSA + NIST + ISO",IF(AND($AA9="Meets CSA maturity",$AB9="Compliant"),"CSA + NIST",IF(AND($AA9="Meets CSA maturity",$AC9="Compliant"),"CSA + ISO",IF(AND($AB9="Compliant",$AC9="Compliant"),"NIST + ISO",IF($AA9="Meets CSA maturity","CSA only",IF($AB9="Compliant","NIST only",IF($AC9="Compliant","ISO only","No mapped framework fully compliant")))))))) -> No mapped framework fully compliant | AE9: Not Provided | AG9: =IFERROR(VLOOKUP($C9,Evidence_Library!$A$2:$C$13,2,FALSE),"Control-specific policy/procedure, implementation record, sample evidence, and monitoring proof.") -> AI policy and acceptable-use standard; AI governance charter; AI Council minutes; approval records; exception logs; role/RACI matrix; training/attestation records; AI risk appetite and escalation procedure. | AH9: =IFERROR(VLOOKUP($C9,Evidence_Library!$A$2:$C$13,3,FALSE),"Inspect design, sample implementation evidence, interview owner, and verify operating effectiveness.") -> Inspect approved policy and governance charter; sample approval records; verify owners and decision logs; interview AI Council or control owner; confirm exceptions and attestations are tracked. | AI9: Not Tested | AM9: Not Assessed
A10: Governance | B10: GOV-05.1 | C10: GOV | D10: 5 | E10: Automated governance evidence and exception lifecycle | F10: Governance posture is visible on a live dashboard fed by source-system telemetry rather than hand-assembled, and policy exceptions move through a tracked lifecycle that closes or renews on schedule. | G10: Automated | H10: All | I10: GRC-01 (governance program policy), GRC-03 (organizational policy reviews), GRC-04 (policy exception process) | J10: GOVERN 1.5; MANAGE 4.1; GOVERN 1; MANAGE 4 | K10: GOVERN 1.5: - Establish policies to allocate appropriate resources and capacity for assessing impacts of AI systems on individuals, communities and society. - Establish policies and procedures for monitoring and addressing AI system performance and trustworthiness, including bias and security problems, across the lifecycle of the system. - Establish policies for AI system incident response, or confirm that existing incident response policies apply to AI systems. - Establish policies to define organizational functions and personnel responsible for AI system monitoring and incident response activities. - Establish mechanisms to enable the sharing of feedback from impacted individuals or communities about negative impacts from AI systems. - Establish mechanisms to provide recourse for impacted individuals or communities to contest problematic AI system outcomes. - Establish opt-out mechanisms. MANAGE 4.1: - Establish and maintain procedures to monitor AI system performance for risks and negative and positive impacts associated with trustworthiness characteristics. - Perform post-deployment TEVV tasks to evaluate AI system validity and reliability, bias and fairness, privacy, and security and resilience. - Evaluate AI system trustworthiness in conditions similar to deployment context of use, and prior to deployment. - Establish and implement red-teaming exercises at a prescribed cadence, and evaluate their efficacy. - Establish procedures for tracking dataset modifications such as data deletion or rectification requests. - Establish mechanisms for regular communication and feedback between relevant AI actors and internal or external stakeholders to capture information about system performance, trustworthiness and impact.… | L10: Direct from AISMM external reference | M10: Clause 9 | N10: Clause 9 – Performance Evaluation: Monitor, measure, analyze, and evaluate the AIMS; perform internal audits; conduct management review at planned intervals. | O10: Direct from AISMM external reference | P10: Use this row as a control objective to assess current state, define target maturity, collect evidence, and remediate gaps. | Q10: CSA AISMM uploaded spreadsheet; NIST AI RMF Playbook uploaded spreadsheet; ISO 42001 checklist uploaded PDF; public CSA/NIST/ISO pages | R10: NIST AI RMF Govern 1.5, Manage 4.1; ISO/IEC 42001 Clause 9 (performance evaluation) | S10: Yes | T10: CSA AISMM; NIST AI RMF; ISO/IEC 42001 | W10: Not Assessed | X10: 0 | Y10: 3 | Z10: =IF($S10="No","N/A",MAX(0,$Y10-$X10)) -> 3 | AA10: =IF($S10="No","N/A",IF($X10>=VALUE($D10),"Meets CSA maturity","Gap to CSA level")) -> Gap to CSA level | AB10: =IF($S10="No","N/A",IF($J10="","Not Mapped",IF(AND($X10>=3,$AE10="Validated"),"Compliant",IF($X10>=1,"Partial","Not Compliant")))) -> Not Compliant | AC10: =IF($S10="No","N/A",IF($M10="","Not Mapped",IF(AND($X10>=3,$AE10="Validated"),"Compliant",IF($X10>=1,"Partial","Not Compliant")))) -> Not Compliant | AD10: =IF($S10="No","N/A",IF(AND($AA10="Meets CSA maturity",$AB10="Compliant",$AC10="Compliant"),"CSA + NIST + ISO",IF(AND($AA10="Meets CSA maturity",$AB10="Compliant"),"CSA + NIST",IF(AND($AA10="Meets CSA maturity",$AC10="Compliant"),"CSA + ISO",IF(AND($AB10="Compliant",$AC10="Compliant"),"NIST + ISO",IF($AA10="Meets CSA maturity","CSA only",IF($AB10="Compliant","NIST only",IF($AC10="Compliant","ISO only","No mapped framework fully compliant")))))))) -> No mapped framework fully compliant | AE10: Not Provided | AG10: =IFERROR(VLOOKUP($C10,Evidence_Library!$A$2:$C$13,2,FALSE),"Control-specific policy/procedure, implementation record, sample evidence, and monitoring proof.") -> AI policy and acceptable-use standard; AI governance charter; AI Council minutes; approval records; exception logs; role/RACI matrix; training/attestation records; AI risk appetite and escalation procedure. | AH10: =IFERROR(VLOOKUP($C10,Evidence_Library!$A$2:$C$13,3,FALSE),"Inspect design, sample implementation evidence, interview owner, and verify operating effectiveness.") -> Inspect approved policy and governance charter; sample approval records; verify owners and decision logs; interview AI Council or control owner; confirm exceptions and attestations are tracked. | AI10: Not Tested | AM10: Not Assessed
A11: Governance | B11: GOV-05.2 | C11: GOV | D11: 5 | E11: Ethics review board with on-change reviews and enforcement authority | F11: A standing AI ethics review board has and demonstrably exercises enforcement authority, halting, modifying, or remediating production AI deployments as needed to meet enterprise AI ethics requirements. The governance function responds to provider and regulatory changes within defined SLAs, so governance is active and current rather than declarative. | G11: Manual | H11: All | I11: GRC-12 (ethics committee), GRC-10 (AI impact assessment), GRC-15 (human supervision), GRC-04 (policy exception process) | J11: GOVERN 1.3; GOVERN 3.2; MANAGE 4.1; MANAGE 4.3; GOVERN 1; GOVERN 3; MANAGE 4 | K11: GOVERN 1.3: - Establish policies to define mechanisms for measuring or understanding an AI system’s potential impacts, e.g., via regular impact assessments at key stages in the AI lifecycle, connected to system impacts and frequency of system updates. - Establish policies to define mechanisms for measuring or understanding the likelihood of an AI system’s impacts and their magnitude at key stages in the AI lifecycle. - Establish policies that define assessment scales for measuring potential AI system impact. Scales may be qualitative, such as red-amber-green (RAG), or may entail simulations or econometric approaches. - Establish policies for assigning an overall risk measurement approach for an AI system, or its important components, e.g., via multiplication or combination of a mapped risk’s impact and likelihood (risk ≈ impact x likelihood).… GOVERN 3.2: - Establish policies and procedures that define and differentiate the various human roles and responsibilities when using, interacting with, or monitoring AI systems. - Establish procedures for capturing and tracking risk information related to human-AI configurations and associated outcomes. - Establish policies for the development of proficiency standards for AI actors carrying out system operation tasks and system oversight tasks. - Establish specified risk management training protocols for AI actors carrying out system operation tasks and system oversight tasks. - Establish policies and procedures regarding AI actor roles, and responsibilities for human oversight of deployed systems.… MANAGE 4.1: - Establish and maintain procedures to monitor AI system performance for risks and negative and positive impacts associated with trustworthiness characteristics. - Perform post-deployment TEVV tasks to evaluate AI system validity and reliability, bias and fairness, privacy, and security and resilience. - Evaluate AI system trustworthiness in conditions similar to deployment context of use, and prior to deployment. - Establish and implement red-teaming exercises at a prescribed cadence, and evaluate their efficacy. - Establish procedures for tracking dataset modifications such as data deletion or rectification requests. - Establish mechanisms for regular communication and feedback between relevant AI actors and internal or external stakeholders to capture information about system performance, trustworthiness and impact.… MANAGE 4.3: - Establish procedures to regularly share information about errors, incidents and negative impacts with relevant stakeholders, operators, practitioners and users, and impacted parties. - Maintain a database of reported errors, near-misses, incidents and negative impacts including date reported, number of reports, assessment of impact and severity, and responses. - Maintain a database of system changes, reason for change, and details of how the change was made, tested and deployed.… | L11: Direct from AISMM external reference | M11: Annex A.10 | N11: Annex A.10 – Third-party and customer relationships: Define lifecycle responsibilities with third parties, manage AI suppliers, capture customer expectations, and review third-party roles through ongoing governance. | O11: Direct from AISMM external reference | P11: Use this row as a control objective to assess current state, define target maturity, collect evidence, and remediate gaps. | Q11: CSA AISMM uploaded spreadsheet; NIST AI RMF Playbook uploaded spreadsheet; ISO 42001 checklist uploaded PDF; public CSA/NIST/ISO pages | R11: NIST AI RMF Govern 1.3, Govern 3.2, Manage 4.1, Manage 4.3; EU AI Act Article 14 (human oversight) and Article 72 (post-market monitoring) concepts; ISO/IEC 42001 Annex A.10 (third-party relationships) | S11: Yes | T11: CSA AISMM; NIST AI RMF; ISO/IEC 42001 | W11: Not Assessed | X11: 0 | Y11: 3 | Z11: =IF($S11="No","N/A",MAX(0,$Y11-$X11)) -> 3 | AA11: =IF($S11="No","N/A",IF($X11>=VALUE($D11),"Meets CSA maturity","Gap to CSA level")) -> Gap to CSA level | AB11: =IF($S11="No","N/A",IF($J11="","Not Mapped",IF(AND($X11>=3,$AE11="Validated"),"Compliant",IF($X11>=1,"Partial","Not Compliant")))) -> Not Compliant | AC11: =IF($S11="No","N/A",IF($M11="","Not Mapped",IF(AND($X11>=3,$AE11="Validated"),"Compliant",IF($X11>=1,"Partial","Not Compliant")))) -> Not Compliant | AD11: =IF($S11="No","N/A",IF(AND($AA11="Meets CSA maturity",$AB11="Compliant",$AC11="Compliant"),"CSA + NIST + ISO",IF(AND($AA11="Meets CSA maturity",$AB11="Compliant"),"CSA + NIST",IF(AND($AA11="Meets CSA maturity",$AC11="Compliant"),"CSA + ISO",IF(AND($AB11="Compliant",$AC11="Compliant"),"NIST + ISO",IF($AA11="Meets CSA maturity","CSA only",IF($AB11="Compliant","NIST only",IF($AC11="Compliant","ISO only","No mapped framework fully compliant")))))))) -> No mapped framework fully compliant | AE11: Not Provided | AG11: =IFERROR(VLOOKUP($C11,Evidence_Library!$A$2:$C$13,2,FALSE),"Control-specific policy/procedure, implementation record, sample evidence, and monitoring proof.") -> AI policy and acceptable-use standard; AI governance charter; AI Council minutes; approval records; exception logs; role/RACI matrix; training/attestation records; AI risk appetite and escalation procedure. | AH11: =IFERROR(VLOOKUP($C11,Evidence_Library!$A$2:$C$13,3,FALSE),"Inspect design, sample implementation evidence, interview owner, and verify operating effectiveness.") -> Inspect approved policy and governance charter; sample approval records; verify owners and decision logs; interview AI Council or control owner; confirm exceptions and attestations are tracked. | AI11: Not Tested | AM11: Not Assessed
A12: Organization Management | B12: ORG-02.1 | C12: ORG | D12: 2 | E12: Enterprise AI service discovery via reconciled telemetry | F12: Security leadership knows which AI services are in use across the enterprise, reconciled across cloud and SaaS billing, identity provider sign-in records for AI services, and CASB or DNS/egress allowlist matches against known AI provider endpoints. AI services adopted outside formal approval channels are visible to the Council. | G12: Manual | H12: All | I12: CCC-06 (change management baseline — establishing the AI service baseline), CCC-07 (detection of baseline deviation — manual at L2) | J12: MAP 1 | K12: MAP 1: Parent AI RMF category/function referenced; use associated subcategory rows for testable control language. | L12: Direct from AISMM external reference | M12: Annex A.3; Annex A.10 | N12: Annex A.3 – Internal organization: Define AI roles and responsibilities; provide reporting and confidential escalation paths; investigate and resolve AI-related concerns. Annex A.10 – Third-party and customer relationships: Define lifecycle responsibilities with third parties, manage AI suppliers, capture customer expectations, and review third-party roles through ongoing governance. | O12: Derived by control theme/domain | P12: Define log schema, retention, access controls, alerting, and incident triage integration. | Q12: CSA AISMM uploaded spreadsheet; NIST AI RMF Playbook uploaded spreadsheet; ISO 42001 checklist uploaded PDF; public CSA/NIST/ISO pages | R12: NIST AI RMF MAP-1; CSA AI Controls Matrix; Gartner AI TRiSM guidance | S12: Yes | T12: CSA AISMM; NIST AI RMF; ISO/IEC 42001 | W12: Not Assessed | X12: 0 | Y12: 3 | Z12: =IF($S12="No","N/A",MAX(0,$Y12-$X12)) -> 3 | AA12: =IF($S12="No","N/A",IF($X12>=VALUE($D12),"Meets CSA maturity","Gap to CSA level")) -> Gap to CSA level | AB12: =IF($S12="No","N/A",IF($J12="","Not Mapped",IF(AND($X12>=3,$AE12="Validated"),"Compliant",IF($X12>=1,"Partial","Not Compliant")))) -> Not Compliant | AC12: =IF($S12="No","N/A",IF($M12="","Not Mapped",IF(AND($X12>=3,$AE12="Validated"),"Compliant",IF($X12>=1,"Partial","Not Compliant")))) -> Not Compliant | AD12: =IF($S12="No","N/A",IF(AND($AA12="Meets CSA maturity",$AB12="Compliant",$AC12="Compliant"),"CSA + NIST + ISO",IF(AND($AA12="Meets CSA maturity",$AB12="Compliant"),"CSA + NIST",IF(AND($AA12="Meets CSA maturity",$AC12="Compliant"),"CSA + ISO",IF(AND($AB12="Compliant",$AC12="Compliant"),"NIST + ISO",IF($AA12="Meets CSA maturity","CSA only",IF($AB12="Compliant","NIST only",IF($AC12="Compliant","ISO only","No mapped framework fully compliant")))))))) -> No mapped framework fully compliant | AE12: Not Provided | AG12: =IFERROR(VLOOKUP($C12,Evidence_Library!$A$2:$C$13,2,FALSE),"Control-specific policy/procedure, implementation record, sample evidence, and monitoring proof.") -> AIMS scope statement; organizational context analysis; interested-party register; operating model; RACI; internal communication records; training plans; management review outputs. | AH12: =IFERROR(VLOOKUP($C12,Evidence_Library!$A$2:$C$13,3,FALSE),"Inspect design, sample implementation evidence, interview owner, and verify operating effectiveness.") -> Confirm AIMS scope and organizational context are documented; sample communications and awareness records; verify role assignment and management review participation. | AI12: Not Tested | AM12: Not Assessed
